Workbook

Sheet 00_使い方
A1: 業務システム調達 ベンダー比較評価シート ─ 使い方
B3: ■ このシートの目的
C4: 比較表を作ることではなく、ベンダーに会う前に「評価軸」と「優先順位」を確定させることです。
C5: 評価軸を後から作ると、提案書の上手いベンダーが勝ちます。順序を逆にしないでください。
B7: ■ 進め方
B8: STEP 0 | C8: 01_重み付け設定 で、6つの大分類に重みを割り振る。プリセットを選んで微調整するのが早い。
C9: ここはベンダーに会う前に決めきる。会った後に重みを変えると、それは評価ではなく後付けの理由づけです。
B10: STEP 1 | C10: 02_比較評価シート にベンダー名を入力する(最大4社)。全シートに自動反映されます。
B11: STEP 2 | C11: 費用を入力する。5年総額(TCO)が自動算出され、コストの点数も自動でつきます。
B12: STEP 3 | C12: 29項目を 1〜5 で評価する。分からない項目は空欄のまま、05_ベンダー質問リスト で確認する。
B13: STEP 4 | C13: 03_稟議用サマリ で総合点・順位・レーダーチャート・稟議文面のたたき台を確認する。
B15: ■ 色の意味
B16: 黄色のセル | C16: 入力欄。ここだけを埋めてください。
B17: 灰色のセル | C17: 自動計算。触ると壊れます。
B19: ■ Must(必須要件)の扱い
C20: Must欄が「○」の項目で 2以下 が1つでもあると、総合点に関わらず「要再検討」と判定されます。
C21: 点数だけで運用すると、必須要件を満たさない会社が総合点で勝ってしまう事故が起きます。
C22: この分離が、このシートで最も重要な仕組みです。判定を無視して進める場合は、理由を稟議に明記してください。
B24: ■ 使うときの注意
B25: 1 | C25: 評点は必ず根拠とセットで。メモ欄が空の点数は、3か月後の自分が説明できません。
B26: 2 | C26: 利用部門の担当者にも同じシートで評価してもらい、点数の差が大きい項目を議論の起点にする。
B27: 3 | C27: 初期費用ではなくTCOで並べる。順位が入れ替わるのが普通です。
B28: 4 | C28: 「自社側に必要な工数」は見積書に出てきません。必ずベンダーに人日で出させてください。
B29: 5 | C29: 評価項目・重みは自社に合わせて足し引きして構いません。ただしベンダーに会う前に確定させること。
B31: ■ 免責
C32: 本シートは調達判断を補助するツールであり、特定の製品・ベンダーの選定結果を保証するものではありません。
C33: 契約・法務・会計上の判断は、必ず自社の該当部門および専門家にご確認ください。

Sheet 01_重み付け設定
A1: STEP 0 評価軸の重み付け設定
B2: 合計が100になるように配分してください。右のプリセットを転記して微調整するのが最短です。
B3: 重みは必ずベンダーに会う前に確定させること。後から変えると評価ではなく後付けの理由づけになります。
B4: 大分類 | C4: 重み(%) | D4: この軸で見るもの | E4: A: 現場業務を変えたくない | F4: B: 予算の制約が厳しい | G4: C: 情シスの人手が少ない | H4: D: 将来の連携・拡張を見据える
A5: C1 | B5: 機能適合 | C5: 25 | D5: 自社の業務要件を満たすか。標準機能で満たせるほど高評価 | E5: 35 | F5: 20 | G5: 20 | H5: 20
A6: C2 | B6: コスト | C6: 20 | D6: 5年総額(TCO)と費用構造の透明性。単年の初期費用では見ない | E6: 15 | F6: 35 | G6: 15 | H6: 15
A7: C3 | B7: 導入・移行負荷 | C7: 15 | D7: 移行の難易度と、自社側に発生する工数。見積書に出てこない領域 | E7: 15 | F7: 15 | G7: 25 | H7: 10
A8: C4 | B8: サポート・保守 | C8: 15 | D8: 稼働後に効く。無償と有償の線引きが明文化されているか | E8: 15 | F8: 10 | G8: 25 | H8: 15
A9: C5 | B9: 拡張性・将来性 | C9: 15 | D9: 5年後に困らないか。連携手段とデータの持ち出し可否 | E9: 10 | F9: 10 | G9: 10 | H9: 30
A10: C6 | B10: ベンダー信頼性 | C10: 10 | D10: 提案の的確さと事業継続性。実績は同業種・同規模で見る | E10: 10 | F10: 10 | G10: 5 | H10: 10
B11: 合計 | C11: =SUM(C5:C10) | D11: =IF(C11=100,"OK 合計100です","※ 合計が100になっていません("&C11&")。調整してください") | E11: =SUM(E5:E10) | F11: =SUM(F5:F10) | G11: =SUM(G5:G10) | H11: =SUM(H5:H10)
B13: 重み付けの決め方
B14: ・「全部大事」は重み付けではありません。必ず差をつけてください。差がつかない配分は判断を先送りしているだけです。
B15: ・迷ったら「この案件が失敗するとしたら、原因は何か」を考え、その軸を重くします。
B16: ・現場の反対で頓挫しそうなら機能適合、情シスの手が足りないなら導入負荷とサポート、が実務的な目安です。
B17: ・重みは利用部門・上長と合意しておくと、稟議での説明がそのまま通ります。

Sheet 02_比較評価シート
A1: 業務システム調達 ベンダー比較評価シート
A3: 案件名
A4: 評価者
A5: 評価日
A7: ■ STEP1 比較するベンダー名を入力する(最大4社)
A8: ベンダー名 → | F8: A社 | G8: B社 | H8: C社 | I8: D社 | J8: ※ ここに入れた社名が全シートに反映されます
A10: ■ STEP2 費用を入力する(5年総額 TCO を自動算出)
C11: 費用項目(税抜・円) | D11: 区分 | F11: =IF(F8="","",F8) | G11: =IF(G8="","",G8) | H11: =IF(H8="","",H8) | I11: =IF(I8="","",I8) | J11: メモ
C12: 初期費用(ライセンス・構築) | D12: 一時
C13: カスタマイズ・追加開発費 | D13: 一時
C14: データ移行費用 | D14: 一時
C15: 自社側の追加コスト(端末・回線・外部委託等) | D15: 一時
C16: 年間ランニング費用(保守・利用料) | D16: 年額
C17: 年間その他費用(法改正対応・VUP等の想定) | D17: 年額
C18: ■ 5年総額(TCO) | D18: 自動 | F18: =IF(COUNT(F12:F17)=0,"",SUM(F12:F15)+SUM(F16:F17)*5) | G18: =IF(COUNT(G12:G17)=0,"",SUM(G12:G15)+SUM(G16:G17)*5) | H18: =IF(COUNT(H12:H17)=0,"",SUM(H12:H15)+SUM(H16:H17)*5) | I18: =IF(COUNT(I12:I17)=0,"",SUM(I12:I15)+SUM(I16:I17)*5) | J18: 一時費用の合計 + 年額の合計×5年
C19: ※ 初期費用の安さで判断しないこと。TCOで並べ替えると順位が入れ替わるのが普通です。
A21: ■ STEP3 各項目を 1〜5 で評価する
A22: 5 = 期待を大きく上回る / 4 = 十分に満たす / 3 = 標準的・条件付きで満たす / 2 = 不足あり、対応策が必要 / 1 = 満たさない
A23: Must 欄が「○」の項目で 2 以下が1つでもあると、総合点に関わらず「要再検討」と判定されます。
A24: 大分類 | B24: No | C24: 評価項目 | D24: 確認の観点(ここを見る) | E24: Must | F24: =IF(F8="","",F8) | G24: =IF(G8="","",G8) | H24: =IF(H8="","",H8) | I24: =IF(I8="","",I8) | J24: メモ・確認結果
A25: 機能適合 | B25: 1 | C25: 必須業務要件の充足度 | D25: 要件定義で「必須」と定めた項目を満たすか。カスタマイズ前提の回答は満たしたと数えない | E25: ○
A26: 機能適合 | B26: 2 | C26: 標準機能での充足率(カスタマイズ不要度) | D26: カスタマイズが増えるほど、バージョンアップ時の追加費用と改修リスクが上がる。「できます」の中身が標準か開発かを必ず分ける | E26: -
A27: 機能適合 | B27: 3 | C27: 任意要件(あれば望ましい)の充足度 | D27: 必須要件と混ぜて評価しない。ここで差がついても足切りの理由にはしない | E27: -
A28: 機能適合 | B28: 4 | C28: 現行業務フローとの整合 | D28: 業務をシステムに合わせる範囲を、事前に利用部門と合意できているか。合意なしの「運用でカバー」は後で必ず揉める | E28: -
A29: 機能適合 | B29: 5 | C29: 画面・操作性(現場が実際に使えるか) | D29: 情シスではなく利用部門にデモを触らせて評価する。1日100回使う画面の操作回数を数える | E29: -
A30: 機能適合 | B30: 6 | C30: 帳票・出力の柔軟性 | D30: 帳票の追加・改変を自社でできるか、都度ベンダー依頼(有償)か。運用開始後に効いてくる | E30: -
A31: コスト | B31: 7 | C31: 5年総額(TCO)の低さ ※費用入力から自動算出 | D31: STEP2の費用入力から自動計算。最安社を5点として相対配点する。手入力しない | E31: - | F31: =IF(COUNT($F$18:$I$18)=0,"",IF(F$18="","",ROUND(MAX(1,MIN(5,5*MIN($F$18:$I$18)/F$18)),1))) | G31: =IF(COUNT($F$18:$I$18)=0,"",IF(G$18="","",ROUND(MAX(1,MIN(5,5*MIN($F$18:$I$18)/G$18)),1))) | H31: =IF(COUNT($F$18:$I$18)=0,"",IF(H$18="","",ROUND(MAX(1,MIN(5,5*MIN($F$18:$I$18)/H$18)),1))) | I31: =IF(COUNT($F$18:$I$18)=0,"",IF(I$18="","",ROUND(MAX(1,MIN(5,5*MIN($F$18:$I$18)/I$18)),1)))
A32: コスト | B32: 8 | C32: 費用構造の透明性 | D32: 見積の内訳が項目ごとに分解されているか。「一式」表記が多いほど後から増える | E32: -
A33: コスト | B33: 9 | C33: 追加費用の発生条件の明確さ | D33: 利用者数の増加、法改正対応、バージョンアップ、問い合わせ超過。どこから課金かを文書で確認 | E33: ○
A34: コスト | B34: 10 | C34: 支払条件・契約期間の柔軟性 | D34: 最低利用期間、途中解約時の扱い、値上げ時の通知条件。SaaSは特に確認 | E34: -
A35: 導入・移行負荷 | B35: 11 | C35: データ移行の難易度と移行方式の妥当性 | D35: 移行対象の範囲、移行できないデータ、名寄せの要否。「移行は御社で」の線引きを明確に | E35: -
A36: 導入・移行負荷 | B36: 12 | C36: 導入期間と自社の希望スケジュールの適合 | D36: 繁忙期・決算期を避けられるか。ベンダー側の要員確保時期も確認する | E36: -
A37: 導入・移行負荷 | B37: 13 | C37: 自社側に必要な工数(人日) | D37: 見積書に絶対に出てこない項目。要件確認、テスト、マスタ整備、現場調整。ここを聞かないと必ず溢れる | E37: ○
A38: 導入・移行負荷 | B38: 14 | C38: 現場教育・マニュアルの提供範囲 | D38: 研修が何回・何名まで無償か。マニュアルは自社編集可能な形式で提供されるか | E38: -
A39: 導入・移行負荷 | B39: 15 | C39: 並行稼働・切替方式のリスク | D39: 一斉切替か段階切替か。切り戻し(ロールバック)の条件と期限が決まっているか | E39: -
A40: サポート・保守 | B40: 16 | C40: 問い合わせ窓口と受付時間 | D40: 受付時間、手段(電話/メール/チャット)、専任か共通か。自社の稼働時間と合っているか | E40: -
A41: サポート・保守 | B41: 17 | C41: 障害時の対応基準(SLA)の明文化 | D41: 一次回答時間、復旧目標、稼働率。口頭ではなく契約書・SLA文書に書かれているかを確認 | E41: ○
A42: サポート・保守 | B42: 18 | C42: 保守契約の範囲(どこからが有償か) | D42: 操作質問、設定変更、マスタ追加、障害調査、データ復旧。無償の線引きを必ず文書で取る | E42: ○
A43: サポート・保守 | B43: 19 | C43: 担当者の業務理解度・体制 | D43: 担当が交代したときの引継ぎ方法。個人の力量に依存していないか | E43: -
... A53: ベンダー信頼性 | B53: 29 | C53: 参考顧客への訪問・ヒアリング可否 | D53: 断られる場合は理由を聞く。応じるベンダーは自信がある。実際に聞けると判断精度が跳ね上がる | E53: -
...

Sheet 03_稟議用サマリ
A1: STEP 4 稟議用サマリ
B2: 案件名: | C2: ='02_比較評価シート'!B3
B4: ■ 総合評価
B5: # | C5: ベンダー | D5: Must判定 | E5: 加重総合点(100点) | F5: 点数順位 | G5: 選定候補順位 | H5: 5年総額(円) | I5: TCO順位 | L5: (補助列)
B6: 1 | C6: =IF('02_比較評価シート'!F8="","",'02_比較評価シート'!F8) | D6: ='02_比較評価シート'!F56 | E6: =IF(SUM($D$13:$D$18)=0,"",SUMPRODUCT($C$13:$C$18,D$13:D$18)/100/5*100) | F6: =IF($E6="","-",RANK($E6,$E$6:$E$9,0)) | G6: =IF($L6="","-",RANK($L6,$L$6:$L$9,0)) | H6: ='02_比較評価シート'!F18 | I6: =IF(ISNUMBER($H6),RANK($H6,$H$6:$H$9,1),"-") | L6: =IF(AND($D6="合格",ISNUMBER($E6)),$E6,"")
B7: 2 | C7: =IF('02_比較評価シート'!G8="","",'02_比較評価シート'!G8) | D7: ='02_比較評価シート'!G56 | E7: =IF(SUM($E$13:$E$18)=0,"",SUMPRODUCT($C$13:$C$18,E$13:E$18)/100/5*100) | F7: =IF($E7="","-",RANK($E7,$E$6:$E$9,0)) | G7: =IF($L7="","-",RANK($L7,$L$6:$L$9,0)) | H7: ='02_比較評価シート'!G18 | I7: =IF(ISNUMBER($H7),RANK($H7,$H$6:$H$9,1),"-") | L7: =IF(AND($D7="合格",ISNUMBER($E7)),$E7,"")
B8: 3 | C8: =IF('02_比較評価シート'!H8="","",'02_比較評価シート'!H8) | D8: ='02_比較評価シート'!H56 | E8: =IF(SUM($F$13:$F$18)=0,"",SUMPRODUCT($C$13:$C$18,F$13:F$18)/100/5*100) | F8: =IF($E8="","-",RANK($E8,$E$6:$E$9,0)) | G8: =IF($L8="","-",RANK($L8,$L$6:$L$9,0)) | H8: ='02_比較評価シート'!H18 | I8: =IF(ISNUMBER($H8),RANK($H8,$H$6:$H$9,1),"-") | L8: =IF(AND($D8="合格",ISNUMBER($E8)),$E8,"")
B9: 4 | C9: =IF('02_比較評価シート'!I8="","",'02_比較評価シート'!I8) | D9: ='02_比較評価シート'!I56 | E9: =IF(SUM($G$13:$G$18)=0,"",SUMPRODUCT($C$13:$C$18,G$13:G$18)/100/5*100) | F9: =IF($E9="","-",RANK($E9,$E$6:$E$9,0)) | G9: =IF($L9="","-",RANK($L9,$L$6:$L$9,0)) | H9: ='02_比較評価シート'!I18 | I9: =IF(ISNUMBER($H9),RANK($H9,$H$6:$H$9,1),"-") | L9: =IF(AND($D9="合格",ISNUMBER($E9)),$E9,"")
B10: ※「選定候補順位」は Must判定が「合格」のベンダーのみを対象にした順位です。点数順位と食い違う場合、見るべきはこちらです。
B11: ■ 大分類別スコア(5点満点)
B12: 大分類 | C12: 重み(%) | D12: =IF('02_比較評価シート'!F8="","",'02_比較評価シート'!F8) | E12: =IF('02_比較評価シート'!G8="","",'02_比較評価シート'!G8) | F12: =IF('02_比較評価シート'!H8="","",'02_比較評価シート'!H8) | G12: =IF('02_比較評価シート'!I8="","",'02_比較評価シート'!I8)
B13: ='01_重み付け設定'!B5 | C13: ='01_重み付け設定'!C5 | D13: ='02_比較評価シート'!F60 | E13: ='02_比較評価シート'!G60 | F13: ='02_比較評価シート'!H60 | G13: ='02_比較評価シート'!I60
B14: ='01_重み付け設定'!B6 | C14: ='01_重み付け設定'!C6 | D14: ='02_比較評価シート'!F61 | E14: ='02_比較評価シート'!G61 | F14: ='02_比較評価シート'!H61 | G14: ='02_比較評価シート'!I61
B15: ='01_重み付け設定'!B7 | C15: ='01_重み付け設定'!C7 | D15: ='02_比較評価シート'!F62 | E15: ='02_比較評価シート'!G62 | F15: ='02_比較評価シート'!H62 | G15: ='02_比較評価シート'!I62
B16: ='01_重み付け設定'!B8 | C16: ='01_重み付け設定'!C8 | D16: ='02_比較評価シート'!F63 | E16: ='02_比較評価シート'!G63 | F16: ='02_比較評価シート'!H63 | G16: ='02_比較評価シート'!I63
B17: ='01_重み付け設定'!B9 | C17: ='01_重み付け設定'!C9 | D17: ='02_比較評価シート'!F64 | E17: ='02_比較評価シート'!G64 | F17: ='02_比較評価シート'!H64 | G17: ='02_比較評価シート'!I64
B18: ='01_重み付け設定'!B10 | C18: ='01_重み付け設定'!C10 | D18: ='02_比較評価シート'!F65 | E18: ='02_比較評価シート'!G65 | F18: ='02_比較評価シート'!H65 | G18: ='02_比較評価シート'!I65
B42: ■ 稟議記載用のたたき台(空欄を埋めて転記してください)
B43: 【選定結果】
C44: ="評価の結果、"&IFERROR(INDEX($C$6:$C$9,MATCH(1,$G$6:$G$9,0)),"(未評価)")&" を選定候補とする。"
B45: 【選定理由】
C46: ="1. 必須要件(Must項目)をすべて満たしていることを確認した。"
C47: ="2. 6つの評価軸に重み付けを行った加重評価で "&IFERROR(TEXT(INDEX($E$6:$E$9,MATCH(1,$G$6:$G$9,0)),"0.0"),"-")&" 点(100点満点)を獲得し、Must合格社の中で最上位である。"
C48: ="3. 5年総額(TCO)は "&IFERROR(TEXT(INDEX($H$6:$H$9,MATCH(1,$G$6:$G$9,0)),"#,##0"),"-")&" 円(税抜)。"
C49: ="4. (定性的な理由をここに追記)"
B50: 【他社を選定しなかった理由】
C51: (ここに記入。落選各社について1〜2行ずつ、決め手となった項目名を挙げて書くと通りやすい)
B52: 【想定リスクと対応】
C53: (ここに記入。評価で 2 以下をつけた項目が、そのままリスク欄の材料になります)
B54: 【比較検討の経緯】
C55: (ここに記入。ベンダー選定の母数、RFP提示日、提案受領日、デモ実施日などを時系列で)

Sheet 04_記入例
A1: 【記入例】業務システム調達 ベンダー比較評価シート
A2: ※ 架空案件の記入例です。実際の評価には 02_比較評価シート を使ってください。
A3: 案件名 | B3: 販売管理システム刷新(製造業・社員120名)
A4: 評価者 | B4: 情報システム課 ◯◯
A5: 評価日 | B5: 2026-06-15
A7: ■ STEP1 比較するベンダー名を入力する(最大4社)
A8: ベンダー名 → | F8: A社(大手パッケージ) | G8: B社(中堅SaaS) | H8: C社(地元SIer/スクラッチ) | J8: ※ ここに入れた社名が全シートに反映されます
A10: ■ STEP2 費用を入力する(5年総額 TCO を自動算出)
C11: 費用項目(税抜・円) | D11: 区分 | F11: =IF(F8="","",F8) | G11: =IF(G8="","",G8) | H11: =IF(H8="","",H8) | I11: =IF(I8="","",I8) | J11: メモ
C12: 初期費用(ライセンス・構築) | D12: 一時 | F12: 8000000 | G12: 1500000 | H12: 12000000 | J12: A社は初年度ライセンス一括。B社は初期設定費のみ
C13: カスタマイズ・追加開発費 | D13: 一時 | F13: 3500000 | G13: 800000 | H13: 0 | J13: A社は帳票9本の改修。C社はスクラッチのため初期費用に内包
C14: データ移行費用 | D14: 一時 | F14: 1200000 | G14: 900000 | H14: 1500000 | J14: 3社とも旧システムからのマスタ移行を含む
C15: 自社側の追加コスト(端末・回線・外部委託等) | D15: 一時 | F15: 800000 | G15: 600000 | H15: 1000000 | J15: 端末更新・回線増強・移行時の派遣要員。ベンダー見積には含まれない
C16: 年間ランニング費用(保守・利用料) | D16: 年額 | F16: 1800000 | G16: 2400000 | H16: 1200000 | J16: A社は保守料、B社は月額利用料×12、C社は保守料
C17: 年間その他費用(法改正対応・VUP等の想定) | D17: 年額 | F17: 200000 | G17: 0 | H17: 400000 | J17: 法改正対応・VUP時の想定。A社は保守に一部含む、C社は都度有償のため厚めに計上
C18: ■ 5年総額(TCO) | D18: 自動 | F18: =IF(COUNT(F12:F17)=0,"",SUM(F12:F15)+SUM(F16:F17)*5) | G18: =IF(COUNT(G12:G17)=0,"",SUM(G12:G15)+SUM(G16:G17)*5) | H18: =IF(COUNT(H12:H17)=0,"",SUM(H12:H15)+SUM(H16:H17)*5) | I18: =IF(COUNT(I12:I17)=0,"",SUM(I12:I15)+SUM(I16:I17)*5) | J18: 一時費用の合計 + 年額の合計×5年
C19: ※ 初期費用の安さで判断しないこと。TCOで並べ替えると順位が入れ替わるのが普通です。
A21: ■ STEP3 各項目を 1〜5 で評価する
A22: 5 = 期待を大きく上回る / 4 = 十分に満たす / 3 = 標準的・条件付きで満たす / 2 = 不足あり、対応策が必要 / 1 = 満たさない
A23: Must 欄が「○」の項目で 2 以下が1つでもあると、総合点に関わらず「要再検討」と判定されます。
A24: 大分類 | B24: No | C24: 評価項目 | D24: 確認の観点(ここを見る) | E24: Must | F24: =IF(F8="","",F8) | G24: =IF(G8="","",G8) | H24: =IF(H8="","",H8) | I24: =IF(I8="","",I8) | J24: メモ・確認結果
A25: 機能適合 | B25: 1 | C25: 必須業務要件の充足度 | D25: 要件定義で「必須」と定めた項目を満たすか。カスタマイズ前提の回答は満たしたと数えない | E25: ○ | F25: 5 | G25: 2 | H25: 5 | J25: A社/C社は標準で充足。B社は3機能が未対応で、うち1つは代替運用も現場が拒否 → 2点
A26: 機能適合 | B26: 2 | C26: 標準機能での充足率(カスタマイズ不要度) | D26: カスタマイズが増えるほど、バージョンアップ時の追加費用と改修リスクが上がる。「できます」の中身が標準か開発かを必ず分ける | E26: - | F26: 4 | G26: 4 | H26: 2 | J26: C社はスクラッチのため標準機能という概念がなく、全量が個別開発。VUPリスクを考慮して2点
A27: 機能適合 | B27: 3 | C27: 任意要件(あれば望ましい)の充足度 | D27: 必須要件と混ぜて評価しない。ここで差がついても足切りの理由にはしない | E27: - | F27: 5 | G27: 3 | H27: 5 | J27: B社は任意要件のうち4件が未対応。ただし足切り対象外
A28: 機能適合 | B28: 4 | C28: 現行業務フローとの整合 | D28: 業務をシステムに合わせる範囲を、事前に利用部門と合意できているか。合意なしの「運用でカバー」は後で必ず揉める | E28: - | F28: 3 | G28: 3 | H28: 5 | J28: A社/B社はパッケージに業務を合わせる必要あり。C社は現行踏襲。現場合意はA社で調整中
A29: 機能適合 | B29: 5 | C29: 画面・操作性(現場が実際に使えるか) | D29: 情シスではなく利用部門にデモを触らせて評価する。1日100回使う画面の操作回数を数える | E29: - | F29: 3 | G29: 5 | H29: 3 | J29: 利用部門3名で実機評価。B社が最も操作回数が少ない。A社は受注入力に2画面必要
A30: 機能適合 | B30: 6 | C30: 帳票・出力の柔軟性 | D30: 帳票の追加・改変を自社でできるか、都度ベンダー依頼(有償)か。運用開始後に効いてくる | E30: - | F30: 4 | G30: 2 | H30: 5 | J30: B社は帳票追加が都度有償(1本8万円〜)。既存帳票の再現に難あり
A31: コスト | B31: 7 | C31: 5年総額(TCO)の低さ ※費用入力から自動算出 | D31: STEP2の費用入力から自動計算。最安社を5点として相対配点する。手入力しない | E31: - | F31: =IF(COUNT($F$18:$I$18)=0,"",IF(F$18="","",ROUND(MAX(1,MIN(5,5*MIN($F$18:$I$18)/F$18)),1))) | G31: =IF(COUNT($F$18:$I$18)=0,"",IF(G$18="","",ROUND(MAX(1,MIN(5,5*MIN($F$18:$I$18)/G$18)),1))) | H31: =IF(COUNT($F$18:$I$18)=0,"",IF(H$18="","",ROUND(MAX(1,MIN(5,5*MIN($F$18:$I$18)/H$18)),1))) | I31: =IF(COUNT($F$18:$I$18)=0,"",IF(I$18="","",ROUND(MAX(1,MIN(5,5*MIN($F$18:$I$18)/I$18)),1)))
A32: コスト | B32: 8 | C32: 費用構造の透明性 | D32: 見積の内訳が項目ごとに分解されているか。「一式」表記が多いほど後から増える | E32: - | F32: 4 | G32: 5 | H32: 3 | J32: B社は月額の内訳が明快。C社は「開発一式」表記が多く、内訳提示を再依頼した
A33: コスト | B33: 9 | C33: 追加費用の発生条件の明確さ | D33: 利用者数の増加、法改正対応、バージョンアップ、問い合わせ超過。どこから課金かを文書で確認 | E33: ○ | F33: 4 | G33: 4 | H33: 3 | J33: 全社とも文書で回答あり。C社は法改正対応が都度見積で、金額レンジの提示を拒否 → 3点
A34: コスト | B34: 10 | C34: 支払条件・契約期間の柔軟性 | D34: 最低利用期間、途中解約時の扱い、値上げ時の通知条件。SaaSは特に確認 | E34: - | F34: 3 | G34: 4 | H34: 4 | J34: B社は年契約で解約金なし。A社は5年縛り、C社は保守3年縛り
A35: 導入・移行負荷 | B35: 11 | C35: データ移行の難易度と移行方式の妥当性 | D35: 移行対象の範囲、移行できないデータ、名寄せの要否。「移行は御社で」の線引きを明確に | E35: - | F35: 3 | G35: 4 | H35: 4 | J35: 移行対象は得意先・商品・在庫の3マスタ。B社はCSV取込ツールあり。A社は移行ツールが有償
A36: 導入・移行負荷 | B36: 12 | C36: 導入期間と自社の希望スケジュールの適合 | D36: 繁忙期・決算期を避けられるか。ベンダー側の要員確保時期も確認する | E36: - | F36: 2 | G36: 5 | H36: 2 | J36: A社は要員確保の都合で着手が4か月後。繁忙期(3月)にテストが重なる → 2点
A37: 導入・移行負荷 | B37: 13 | C37: 自社側に必要な工数(人日) | D37: 見積書に絶対に出てこない項目。要件確認、テスト、マスタ整備、現場調整。ここを聞かないと必ず溢れる | E37: ○ | F37: 3 | G37: 4 | H37: 3 | J37: 自社工数の見積:A社 45人日 / B社 28人日 / C社 40人日。全社から人日で回答を取得済み
A38: 導入・移行負荷 | B38: 14 | C38: 現場教育・マニュアルの提供範囲 | D38: 研修が何回・何名まで無償か。マニュアルは自社編集可能な形式で提供されるか | E38: - | F38: 4 | G38: 4 | H38: 3 | J38: A社は研修2回まで無償。C社は1回のみで追加は有償
A39: 導入・移行負荷 | B39: 15 | C39: 並行稼働・切替方式のリスク | D39: 一斉切替か段階切替か。切り戻し(ロールバック)の条件と期限が決まっているか | E39: - | F39: 3 | G39: 4 | H39: 3 | J39: B社のみ部門単位の段階切替が可能。A社/C社は一斉切替で切り戻し期限は当日中
A40: サポート・保守 | B40: 16 | C40: 問い合わせ窓口と受付時間 | D40: 受付時間、手段(電話/メール/チャット)、専任か共通か。自社の稼働時間と合っているか | E40: - | F40: 4 | G40: 3 | H40: 5 | J40: C社は地元で往訪対応可。B社はチャット中心で電話は上位プランのみ
A41: サポート・保守 | B41: 17 | C41: 障害時の対応基準(SLA)の明文化 | D41: 一次回答時間、復旧目標、稼働率。口頭ではなく契約書・SLA文書に書かれているかを確認 | E41: ○ | F41: 5 | G41: 4 | H41: 3 | J41: A社はSLA文書あり(一次回答2時間)。C社はSLA文書がなく、契約書に追記を要請中 → 3点
A42: サポート・保守 | B42: 18 | C42: 保守契約の範囲(どこからが有償か) | D42: 操作質問、設定変更、マスタ追加、障害調査、データ復旧。無償の線引きを必ず文書で取る | E42: ○ | F42: 4 | G42: 4 | H42: 3 | J42: C社は「操作質問は有償」の線引きが曖昧。A社/B社は範囲一覧を文書で受領済み → C社3点
A43: サポート・保守 | B43: 19 | C43: 担当者の業務理解度・体制 | D43: 担当が交代したときの引継ぎ方法。個人の力量に依存していないか | E43: - | F43: 3 | G43: 3 | H43: 5 | J43: C社は担当が当社業務を熟知。ただし1名依存で、交代時の体制に不安あり
...

Sheet 05_ベンダー質問リスト
A1: ベンダーへの質問リスト(RFP・提案依頼時にそのまま使えます)
B2: 評価項目を埋めるために必要な質問を並べています。提案依頼時に添付するか、デモ・ヒアリングの場で使ってください。
B3: 重要なのは「答えられるか」だけでなく「文書で出せるか」です。口頭回答は、確認済みに数えないでください。
A5: No | B5: 分類 | C5: 質問内容 | D5: なぜ聞くか(回答をどう使うか) | E5: =IF('02_比較評価シート'!F8="","",'02_比較評価シート'!F8) | F5: =IF('02_比較評価シート'!G8="","",'02_比較評価シート'!G8) | G5: =IF('02_比較評価シート'!H8="","",'02_比較評価シート'!H8) | H5: =IF('02_比較評価シート'!I8="","",'02_比較評価シート'!I8)
A6: 1 | B6: 機能適合 | C6: ご提案の機能のうち、標準機能と個別開発をそれぞれ一覧で分けていただけますか | D6: 「できます」の中身を分解する。個別開発が多いほど費用とVUPリスクが上がる
A7: 2 | B7: 機能適合 | C7: 当社の必須要件◯番について、標準機能のどの画面で実現されますか | D7: デモで実物を見せてもらう。資料上の○は当てにならない
A8: 3 | B8: 機能適合 | C8: 帳票の追加・レイアウト変更は当社側で可能ですか。可能な範囲はどこまでですか | D8: 都度依頼(有償)だと運用開始後に効いてくる
A9: 4 | B9: 機能適合 | C9: 利用部門の担当者が実機を触れる環境をご用意いただけますか | D9: 情シスの評価と現場の評価はズレる。現場が触らないまま決めると定着しない
A10: 5 | B10: コスト | C10: 見積の内訳を、ライセンス/構築/カスタマイズ/移行/教育に分けていただけますか | D10: 「一式」を分解させる。分解できない項目は後から増える
A11: 6 | B11: コスト | C11: 5年間の総額をお示しいただけますか。年度ごとの内訳もお願いします | D11: 初期費用の安さで釣る提案を排除する。判断は必ずTCOで行う
A12: 7 | B12: コスト | C12: 利用者が◯名増えた場合、費用はどう変わりますか | D12: 5年後の想定規模で試算させる。段階課金の閾値を把握する
A13: 8 | B13: コスト | C13: 法改正対応の費用は保守料に含まれますか、別途見積ですか | D13: ここが別料金だと、毎年の想定外支出が発生する
A14: 9 | B14: コスト | C14: 契約の最低利用期間と、途中解約時の取り扱いを教えてください | D14: 失敗したときの退出コストを事前に把握する
A15: 10 | B15: コスト | C15: 値上げが発生する場合の通知時期と条件を教えてください | D15: SaaSでは特に重要。予算計画が立てられるか
A16: 11 | B16: 導入・移行負荷 | C16: 本プロジェクトで当社側に発生する作業と工数(人日)を、工程別にお示しください | D16: 最重要質問。ここを答えられないベンダーは進行管理も期待できない
A17: 12 | B17: 導入・移行負荷 | C17: 移行できないデータ、移行に制約があるデータはありますか | D17: 「全部移行できます」は要注意。必ず制約はある
... A35: 30 | B35: ベンダー信頼性 | C35: 提案いただいた内容のうち、当社のヒアリング結果を反映した箇所はどこですか | D35: 汎用資料の流用かどうかが一発で分かる
